Workbook

Sheet Lista de Precio 
A1: Description | B1: Qty | C1: Price | D1: Ventas | E1: Inventario
A2: ADIDAS ICE DIVE MEN 3.4 OZ. EDT | B2: 0 | C2: 28.5 | D2: 1 | E2: Csar 1
A3: ADIDAS TEAM FORCE MEN 3.4 OZ. EDT | B3: 0 | C3: 28.5 | D3: 1 | E3: Csar 1
A4: ADIDAS VICTORY LEAGUE MEN 3.4 OZ. EDT SP-NEW UPC | B4: 0 | C4: 28.5 | D4: 1 | E4: Csar 1
A5: ADIDAS VICTORY LEAGUE MEN 3.4 OZ. SP (NEW UPC) | B5: 0 | C5: 28.5 | D5: 1 | E5: Csar 1
A6: AFNAN 9AM DIVE UNISEX 3.4 OZ. EDP SP | B6: 0 | C6: 60 | D6: 2 | E6: Yonathan
A7: AFNAN 9AM WOMEN 3.4 OZ. EDP SP | B7: 0 | C7: 60 | D7: 2 | E7: Nani
A8: AFNAN 9PM MEN 3.4 OZ. EDP SP | B8: 0 | C8: 60 | D8: 3 | E8: Luis 1, Ciribeth, Salcedo
A9: AFNAN 9PM REBEL (RED) UNISEX 3.4 OZ EDP SP | B9: 0 | C9: 65 | D9: 3 | E9: Cesar 1, Reinaldo, Wenrit
A10: AL HARAMAIN AMBER OUD GOLD UNISEX 2.0 OZ EDP SP | B10: 0 | C10: 73 | D10: 2 | E10: Csar 1, Yeny
A11: AL HARAMAIN AMBER OUD PRIVATE EDITION UNISEX 2.0 OZ EDP SP | B11: 0 | C11: 85 | D11: 1 | E11: Yeni Geneis
A12: AL HARAMAIN AMBER OUD RUBY WOMEN 3.3 OZ. EDP SP | B12: 0 | C12: 85 | D12: 1 | E12: Yeni Geneis
A13: ΑΝΤΟΝΙΟO BANDERAS BLUE SEDUCTION MEN 3.4 OZ EDT SP-NEW UPC | B13: 1 | C13: 40 | D13: 2 | E13: Csar 2
... A32: CAROLINA HERRERA BAD BOY COBALTO MEN 3.4 OZ EDP SP | B32: 0 | C32: 130 | D32: 1 | E32: Cesar
A33: CAROLINA HERRERA CHIC WOMAN 2.7 OZ. EDP SP | B33: 0 | C33: 65 | D33: Csar 1 | E33: Luis 1, Yelis 1, Csar 1
A34: CLINIQUE HAPPY WOMEN 3.4 OZ. EDP SPRAY | B34: 0 | C34: 60 | D34: 2 | E34: Cesar 1, Wendy, Milana
A35: DIESEL PLUS PLUS MEN 2.5 OZ. EDT | B35: 0 | C35: 40 | D35: 4 | E35: Wilson, Yelismar
A36: DIESEL PLUS PLUS WOMAN 2.5 OZ. EDT | B36: 0 | C36: 40 | D36: 2 | E36: Genesis, Kristel,
A37: DIESEL ZERO PLUS RED WOMAN 2.5 OZ. EDT | B37: 0 | C37: 40 | D37: 0 | E37: , Csar 2
A38: KIDS DISNEY GUARDIANS OF THE GALAXY BY MARVEL MEN 3.3 OZ EDT SP-AIR VAL | B38: 0 | C38: 30 | D38: 1 | E38: Santigo
A39: KIDS DISNEY MINNIE MOUSE 3.4 OZ. EDT SP - AIR VAL | B39: 0 | C39: 30 | D39: 1 | E39: Ahilin
A40: LATTAFA YARA MOI WOMEN 3.4 OZ EDP SP | B40: 0 | C40: 55 | D40: 3 | E40: Michell, Ciribeth
A41: LATTAFA YARA TOUS WOMEN 3.4 OZ. EDP SP | B41: 2 | C41: 55 | D41: 1 | E41: Maria
A42: MOSCHINO ΤΟΥ ΒΟΥ ΜΕΝ 3.4 OZ. EDP SP | B42: 0 | C42: 85 | D42: 0 | E42: Csar 1
A43: PARIS HILTON GOLD RUSH MEN 3.4 OZ. EDT SP | B43: 0 | C43: 50 | D43: 0 | E43: Csar 1
A44: PARIS HILTON WOMEN 3.4 OZ. EDP SP | B44: 0 | C44: 50 | D44: 3 | E44: Yelis , Moraima, Luis1, Alvaro Tomassi
A45: PERRY ELLIS 360 COLLECTION ROSE WOMEN 3.4 OZ. SPRAY | B45: 2 | C45: 45 | D45: 2 | E45: Yaya, Yajaira
... A55: Stalin 53 (Pedido anterior) | B55: 1 | C55: 50 | D55: 0 | E55: Pedido anterior
A56: Club de niut Sillje | B56: 0 | C56: 55
A57: Nautica | B57: 0 | C57: 40 | E57: Pedido anterior
A58: SWISS ARMY ALTITUDE MEN 3.4 OZ. EDT SPRAY | B58: 0 | C58: 50 | E58: Pedido anterior
A59: Afnan Violet Bouquet woman (LUIS) | B59: 0 | C59: 55 | E59: Luis Rivera
A60: ARMAF ODYSSEY WHITE MEN 3.4 OZ. EDP SPR | B60: 1 | C60: 55
A61: LATTAFA ASAD MEN 3.4 OZ. EDP SP | B61: 2 | C61: 60
A62: LATTAFA BADEE AL OUD HONOR AND GLORY UNISEX 3.4 OZ | B62: 2 | C62: 60
A63: LATTAFA BADEE AL OUD NOBLE BLUSH 3.4 OZ EDP SP | B63: 1 | C63: 60
A64: LATTAFA YARA CANDY WOMEN 3.4 OZ EDP SP | B64: 2 | C64: 60
A65: PERRY ELLIS 360 RED MEN 3.4 OZ. EDT SPRAY | B65: 1 | C65: 65
A66: RASASI HAWAS BLACK MEN 3.4 OZ EDP SP | B66: 0 | C66: 60 | D66: 1 | E66: Yarol Ocando
A67: PERRY ELLIS 360 RED MEN 3.4 OZ. EDT SPRAY | B67: 1 | C67: 55
...

Sheet Ventas
B3: CLIENTES
A6: N° | B6: Codigo | C6: Cliente | D6: Producto | E6: Precio | F6: Fecha | G6: Pago 1 | H6: Pago 2 | I6: Pago 3 | J6: Pago 4 | K6: Pago 5 | L6: Pago 6 | M6: Pago 7 | N6: Por pagar | O6: Fin Credito | P6: NOTA
A7: 1 | B7: 101 | C7: =IF(ISERROR(VLOOKUP(B7,CLIENTES!A:B,2,0)),"",VLOOKUP(B7,CLIENTES!A:B,2,0)) -> Gabriela Maykel | D7: BRITNEY SPEARS FANTASY HIDDEN WOMAN 3.3 OZ. EDP SP | E7: =IF(ISERROR(VLOOKUP(D7,'Lista de Precio '!A:C,3,0)),"",VLOOKUP(D7,'Lista de Precio '!A:C,3,0)) -> 45 | F7: 45837 | G7: 10 | H7: 10 | I7: 5 | J7: 10 | K7: 5 | L7: 5 | N7: =IF(D7="","",E7-G7-H7-I7-J7-K7-L7-M7) -> 0 | O7: 45898
A8: 2 | B8: 102 | C8: =IF(ISERROR(VLOOKUP(B8,CLIENTES!A:B,2,0)),"",VLOOKUP(B8,CLIENTES!A:B,2,0)) -> Genesis Torres | D8: ARIANA GRANDE SWEET LIKE CANDY WOMEN 3.4 OZ. EDP SP | E8: =IF(ISERROR(VLOOKUP(D8,'Lista de Precio '!A:C,3,0)),"",VLOOKUP(D8,'Lista de Precio '!A:C,3,0)) -> 75 | F8: 45837 | G8: 20 | H8: 20 | I8: 20 | J8: 15 | N8: =IF(D8="","",E8-G8-H8-I8-J8-K8-L8-M8) -> 0 | O8: 45898
A9: 3 | B9: 102 | C9: =IF(ISERROR(VLOOKUP(B9,CLIENTES!A:B,2,0)),"",VLOOKUP(B9,CLIENTES!A:B,2,0)) -> Genesis Torres | D9: ARIANA GRANDE CLOUD WOMEN 3.4 OZ. EDP SP | E9: =IF(ISERROR(VLOOKUP(D9,'Lista de Precio '!A:C,3,0)),"",VLOOKUP(D9,'Lista de Precio '!A:C,3,0)) -> 100 | F9: 45867 | G9: 20 | H9: 20 | I9: 20 | J9: 15 | K9: 25 | N9: =IF(D9="","",E9-G9-H9-I9-J9-K9-L9-M9) -> 0 | O9: 45898
A10: 4 | B10: 103 | C10: =IF(ISERROR(VLOOKUP(B10,CLIENTES!A:B,2,0)),"",VLOOKUP(B10,CLIENTES!A:B,2,0)) -> Wenrit Corro | D10: AFNAN 9PM REBEL (RED) UNISEX 3.4 OZ EDP SP | E10: =IF(ISERROR(VLOOKUP(D10,'Lista de Precio '!A:C,3,0)),"",VLOOKUP(D10,'Lista de Precio '!A:C,3,0)) -> 65 | F10: 45837 | G10: 20 | H10: 20 | I10: 20 | J10: 5 | N10: =IF(D10="","",E10-G10-H10-I10-J10-K10-L10-M10) -> 0 | O10: 45898 | P10: Luis Barbero
A11: 5 | B11: 104 | C11: =IF(ISERROR(VLOOKUP(B11,CLIENTES!A:B,2,0)),"",VLOOKUP(B11,CLIENTES!A:B,2,0)) -> Maria Quintana | D11: LATTAFA YARA TOUS WOMEN 3.4 OZ. EDP SP | E11: =IF(ISERROR(VLOOKUP(D11,'Lista de Precio '!A:C,3,0)),"",VLOOKUP(D11,'Lista de Precio '!A:C,3,0)) -> 55 | F11: 45837 | G11: 20 | H11: 20 | I11: 15 | N11: =IF(D11="","",E11-G11-H11-I11-J11-K11-L11-M11) -> 0 | O11: 45898
A12: 6 | B12: 105 | C12: =IF(ISERROR(VLOOKUP(B12,CLIENTES!A:B,2,0)),"",VLOOKUP(B12,CLIENTES!A:B,2,0)) -> Yonathan Gamez | D12: AFNAN 9AM DIVE UNISEX 3.4 OZ. EDP SP | E12: =IF(ISERROR(VLOOKUP(D12,'Lista de Precio '!A:C,3,0)),"",VLOOKUP(D12,'Lista de Precio '!A:C,3,0)) -> 60 | F12: 45837 | G12: 25 | H12: 20 | I12: 15 | N12: =IF(D12="","",E12-G12-H12-I12-J12-K12-L12-M12) -> 0 | O12: 45897
A13: 7 | B13: 105 | C13: =IF(ISERROR(VLOOKUP(B13,CLIENTES!A:B,2,0)),"",VLOOKUP(B13,CLIENTES!A:B,2,0)) -> Yonathan Gamez | D13: Stalin 53 (Pedido anterior) | E13: =IF(ISERROR(VLOOKUP(D13,'Lista de Precio '!A:C,3,0)),"",VLOOKUP(D13,'Lista de Precio '!A:C,3,0)) -> 50 | F13: 45837 | G13: 45 | H13: 5 | N13: =IF(D13="","",E13-G13-H13-I13-J13-K13-L13-M13) -> 0 | O13: 45898
A14: 8 | B14: 106 | C14: =IF(ISERROR(VLOOKUP(B14,CLIENTES!A:B,2,0)),"",VLOOKUP(B14,CLIENTES!A:B,2,0)) -> Nani | D14: AFNAN 9AM WOMEN 3.4 OZ. EDP SP | E14: =IF(ISERROR(VLOOKUP(D14,'Lista de Precio '!A:C,3,0)),"",VLOOKUP(D14,'Lista de Precio '!A:C,3,0)) -> 60 | F14: 45834 | G14: 30 | H14: 30 | N14: =IF(D14="","",E14-G14-H14-I14-J14-K14-L14-M14) -> 0 | O14: 45897
A15: 9 | B15: 107 | C15: =IF(ISERROR(VLOOKUP(B15,CLIENTES!A:B,2,0)),"",VLOOKUP(B15,CLIENTES!A:B,2,0)) -> Yusneidy Alarcon | D15: ARMAF CLUB DE NUIT URBAN ELIXIR MEN 3.6 OZ EDP SP | E15: =IF(ISERROR(VLOOKUP(D15,'Lista de Precio '!A:C,3,0)),"",VLOOKUP(D15,'Lista de Precio '!A:C,3,0)) -> 60 | F15: 45834 | G15: 30 | H15: 10 | I15: 20 | N15: =IF(D15="","",E15-G15-H15-I15-J15-K15-L15-M15) -> 0 | O15: 45897
A16: 10 | B16: 107 | C16: =IF(ISERROR(VLOOKUP(B16,CLIENTES!A:B,2,0)),"",VLOOKUP(B16,CLIENTES!A:B,2,0)) -> Yusneidy Alarcon | D16: PERRY ELLIS 360 COLLECTION ROSE WOMEN 3.4 OZ. SPRAY | E16: =IF(ISERROR(VLOOKUP(D16,'Lista de Precio '!A:C,3,0)),"",VLOOKUP(D16,'Lista de Precio '!A:C,3,0)) -> 45 | F16: 45834 | G16: 30 | H16: 10 | N16: =IF(D16="","",E16-G16-H16-I16-J16-K16-L16-M16) -> 5 | O16: 45897
A17: 11 | B17: 108 | C17: =IF(ISERROR(VLOOKUP(B17,CLIENTES!A:B,2,0)),"",VLOOKUP(B17,CLIENTES!A:B,2,0)) -> Yajaira | D17: PERRY ELLIS 360 COLLECTION ROSE WOMEN 3.4 OZ. SPRAY | E17: =IF(ISERROR(VLOOKUP(D17,'Lista de Precio '!A:C,3,0)),"",VLOOKUP(D17,'Lista de Precio '!A:C,3,0)) -> 45 | F17: 45834 | G17: 20 | N17: =IF(D17="","",E17-G17-H17-I17-J17-K17-L17-M17) -> 25 | O17: 45898
A18: 12 | B18: 108 | C18: =IF(ISERROR(VLOOKUP(B18,CLIENTES!A:B,2,0)),"",VLOOKUP(B18,CLIENTES!A:B,2,0)) -> Yajaira | D18: RASASI HAWAS ICE MEN 3.4 OZ EDP SP | E18: =IF(ISERROR(VLOOKUP(D18,'Lista de Precio '!A:C,3,0)),"",VLOOKUP(D18,'Lista de Precio '!A:C,3,0)) -> 60 | F18: 45834 | G18: 50 | N18: =IF(D18="","",E18-G18-H18-I18-J18-K18-L18-M18) -> 10 | O18: 45897
A19: 13 | B19: 108 | C19: =IF(ISERROR(VLOOKUP(B19,CLIENTES!A:B,2,0)),"",VLOOKUP(B19,CLIENTES!A:B,2,0)) -> Yajaira | D19: Nautica | E19: =IF(ISERROR(VLOOKUP(D19,'Lista de Precio '!A:C,3,0)),"",VLOOKUP(D19,'Lista de Precio '!A:C,3,0)) -> 40 | F19: 45834 | G19: 20 | N19: =IF(D19="","",E19-G19-H19-I19-J19-K19-L19-M19) -> 20 | O19: 45898
A20: 14 | B20: 109 | C20: =IF(ISERROR(VLOOKUP(B20,CLIENTES!A:B,2,0)),"",VLOOKUP(B20,CLIENTES!A:B,2,0)) -> Maria Mercedez | D20: BRITNEY SPEARS FANTASY WOMAN 3.4 OZ. EDP SP | E20: =IF(ISERROR(VLOOKUP(D20,'Lista de Precio '!A:C,3,0)),"",VLOOKUP(D20,'Lista de Precio '!A:C,3,0)) -> 45 | F20: 45838 | G20: 20 | N20: =IF(D20="","",E20-G20-H20-I20-J20-K20-L20-M20) -> 25 | O20: 45899
A21: 15 | B21: 110 | C21: =IF(ISERROR(VLOOKUP(B21,CLIENTES!A:B,2,0)),"",VLOOKUP(B21,CLIENTES!A:B,2,0)) -> Milana Medina | D21: CLINIQUE HAPPY WOMEN 3.4 OZ. EDP SPRAY | E21: =IF(ISERROR(VLOOKUP(D21,'Lista de Precio '!A:C,3,0)),"",VLOOKUP(D21,'Lista de Precio '!A:C,3,0)) -> 60 | F21: 45838 | G21: 20 | H21: 15 | I21: 10 | J21: 15 | N21: =IF(D21="","",E21-G21-H21-I21-J21-K21-L21-M21) -> 0 | O21: 45899
A22: 16 | B22: 111 | C22: =IF(ISERROR(VLOOKUP(B22,CLIENTES!A:B,2,0)),"",VLOOKUP(B22,CLIENTES!A:B,2,0)) -> Gregorio Salcedo | D22: ARMAF CLUB DE NUIT WOMEN 3.6 OZ. EDP SP | E22: =IF(ISERROR(VLOOKUP(D22,'Lista de Precio '!A:C,3,0)),"",VLOOKUP(D22,'Lista de Precio '!A:C,3,0)) -> 55 | F22: 45838 | G22: 40 | H22: 15 | N22: =IF(D22="","",E22-G22-H22-I22-J22-K22-L22-M22) -> 0 | O22: 45899
A23: 17 | B23: 111 | C23: =IF(ISERROR(VLOOKUP(B23,CLIENTES!A:B,2,0)),"",VLOOKUP(B23,CLIENTES!A:B,2,0)) -> Gregorio Salcedo | D23: AFNAN 9PM MEN 3.4 OZ. EDP SP | E23: =IF(ISERROR(VLOOKUP(D23,'Lista de Precio '!A:C,3,0)),"",VLOOKUP(D23,'Lista de Precio '!A:C,3,0)) -> 60 | F23: 45838 | G23: 40 | H23: 20 | N23: =IF(D23="","",E23-G23-H23-I23-J23-K23-L23-M23) -> 0 | O23: 45899
A24: 18 | B24: 112 | C24: =IF(ISERROR(VLOOKUP(B24,CLIENTES!A:B,2,0)),"",VLOOKUP(B24,CLIENTES!A:B,2,0)) -> Anyi Castillo | D24: ARMAF CLUB DE NUIT WOMEN 3.6 OZ. EDP SP | E24: =IF(ISERROR(VLOOKUP(D24,'Lista de Precio '!A:C,3,0)),"",VLOOKUP(D24,'Lista de Precio '!A:C,3,0)) -> 55 | F24: 45838 | G24: 10 | H24: 10 | I24: 20 | J24: 15 | N24: =IF(D24="","",E24-G24-H24-I24-J24-K24-L24-M24) -> 0 | O24: 45899
A25: 20 | B25: 114 | C25: =IF(ISERROR(VLOOKUP(B25,CLIENTES!A:B,2,0)),"",VLOOKUP(B25,CLIENTES!A:B,2,0)) -> Rosangela Medina | D25: ARMAF CHECKMATE QUEEN WOMEN 3.4 OZ EDP SP | E25: =IF(ISERROR(VLOOKUP(D25,'Lista de Precio '!A:C,3,0)),"",VLOOKUP(D25,'Lista de Precio '!A:C,3,0)) -> 65 | F25: 45838 | G25: 15 | H25: 15 | I25: 15 | J25: 10 | K25: 10 | N25: =IF(D25="","",E25-G25-H25-I25-J25-K25-L25-M25) -> 0 | O25: 45838
A26: 21 | B26: 115 | C26: =IF(ISERROR(VLOOKUP(B26,CLIENTES!A:B,2,0)),"",VLOOKUP(B26,CLIENTES!A:B,2,0)) -> Yuli R | D26: PERRY ELLIS 360 COLLECTION MAGNETIC PINK WOMEN 3.4 OZ EDP SP | E26: =IF(ISERROR(VLOOKUP(D26,'Lista de Precio '!A:C,3,0)),"",VLOOKUP(D26,'Lista de Precio '!A:C,3,0)) -> 50 | F26: 45838 | G26: 20 | H26: 20 | I26: 20 | N26: =IF(D26="","",E26-G26-H26-I26-J26-K26-L26-M26) -> -10 | O26: 45838
A27: 22 | B27: 116 | C27: =IF(ISERROR(VLOOKUP(B27,CLIENTES!A:B,2,0)),"",VLOOKUP(B27,CLIENTES!A:B,2,0)) -> Neuris | D27: BRITNEY SPEARS PREROGATIVE RAVE WOMAN 3.4 OZ. EDP SP | E27: =IF(ISERROR(VLOOKUP(D27,'Lista de Precio '!A:C,3,0)),"",VLOOKUP(D27,'Lista de Precio '!A:C,3,0)) -> 45 | F27: 45838 | G27: 20 | H27: 20 | I27: 5 | N27: =IF(D27="","",E27-G27-H27-I27-J27-K27-L27-M27) -> 0 | O27: 45899
A28: 24 | B28: 118 | C28: =IF(ISERROR(VLOOKUP(B28,CLIENTES!A:B,2,0)),"",VLOOKUP(B28,CLIENTES!A:B,2,0)) -> Wilson Gonzales | D28: DIESEL PLUS PLUS MEN 2.5 OZ. EDT | E28: =IF(ISERROR(VLOOKUP(D28,'Lista de Precio '!A:C,3,0)),"",VLOOKUP(D28,'Lista de Precio '!A:C,3,0)) -> 40 | F28: 45838 | G28: 15 | H28: 25 | N28: =IF(D28="","",E28-G28-H28-I28-J28-K28-L28-M28) -> 0 | O28: 45899
A29: 25 | B29: 119 | C29: =IF(ISERROR(VLOOKUP(B29,CLIENTES!A:B,2,0)),"",VLOOKUP(B29,CLIENTES!A:B,2,0)) -> Hector Hidromaticos | D29: RASASI HAWAS ICE MEN 3.4 OZ EDP SP | E29: =IF(ISERROR(VLOOKUP(D29,'Lista de Precio '!A:C,3,0)),"",VLOOKUP(D29,'Lista de Precio '!A:C,3,0)) -> 60 | F29: 45838 | G29: 40 | H29: 20 | N29: =IF(D29="","",E29-G29-H29-I29-J29-K29-L29-M29) -> 0 | O29: 45899 | P29: 13$ cuenta Vieja
A30: 26 | B30: 119 | C30: =IF(ISERROR(VLOOKUP(B30,CLIENTES!A:B,2,0)),"",VLOOKUP(B30,CLIENTES!A:B,2,0)) -> Hector Hidromaticos | D30: BRITNEY SPEARS PREROGATIVE RAVE WOMAN 3.4 OZ. EDP SP | E30: =IF(ISERROR(VLOOKUP(D30,'Lista de Precio '!A:C,3,0)),"",VLOOKUP(D30,'Lista de Precio '!A:C,3,0)) -> 45 | F30: 45838 | G30: 20 | H30: 20 | I30: 5 | N30: =IF(D30="","",E30-G30-H30-I30-J30-K30-L30-M30) -> 0 | O30: 45899 | P30: queda en 53
A31: 27 | B31: 120 | C31: =IF(ISERROR(VLOOKUP(B31,CLIENTES!A:B,2,0)),"",VLOOKUP(B31,CLIENTES!A:B,2,0)) -> Junior Hidromaticos | D31: ARMAF CLUB NUIT INTENSE WOMEN 3.6 OZ. EDP SP | E31: =IF(ISERROR(VLOOKUP(D31,'Lista de Precio '!A:C,3,0)),"",VLOOKUP(D31,'Lista de Precio '!A:C,3,0)) -> 55 | F31: 45838 | G31: 25 | H31: 20 | I31: 5 | N31: =IF(D31="","",E31-G31-H31-I31-J31-K31-L31-M31) -> 5 | O31: 45899 | P31: 5
A32: 28 | B32: 120 | C32: =IF(ISERROR(VLOOKUP(B32,CLIENTES!A:B,2,0)),"",VLOOKUP(B32,CLIENTES!A:B,2,0)) -> Junior Hidromaticos | D32: ARMAF ODYSSEY SPECTRA MEN 3.4 OZ EDP SP | E32: =IF(ISERROR(VLOOKUP(D32,'Lista de Precio '!A:C,3,0)),"",VLOOKUP(D32,'Lista de Precio '!A:C,3,0)) -> 65 | F32: 45838 | G32: 20 | H32: 20 | I32: 20 | N32: =IF(D32="","",E32-G32-H32-I32-J32-K32-L32-M32) -> 5 | O32: 45899
A33: 29 | B33: 121 | C33: =IF(ISERROR(VLOOKUP(B33,CLIENTES!A:B,2,0)),"",VLOOKUP(B33,CLIENTES!A:B,2,0)) -> Grise Hidromaticos | D33: PERRY ELLIS 360 COLLECTION WOMEN 3.4 OZ. EDP SPRAY | E33: =IF(ISERROR(VLOOKUP(D33,'Lista de Precio '!A:C,3,0)),"",VLOOKUP(D33,'Lista de Precio '!A:C,3,0)) -> 45 | F33: 45838 | G33: 20 | H33: 20 | N33: =IF(D33="","",E33-G33-H33-I33-J33-K33-L33-M33) -> 5 | O33: 45899
A34: 30 | B34: 122 | C34: =IF(ISERROR(VLOOKUP(B34,CLIENTES!A:B,2,0)),"",VLOOKUP(B34,CLIENTES!A:B,2,0)) -> Yeni Peña | D34: AL HARAMAIN AMBER OUD RUBY WOMEN 3.3 OZ. EDP SP | E34: =IF(ISERROR(VLOOKUP(D34,'Lista de Precio '!A:C,3,0)),"",VLOOKUP(D34,'Lista de Precio '!A:C,3,0)) -> 85 | F34: 45838 | G34: 30 | H34: 25 | I34: 25 | J34: 5 | N34: =IF(D34="","",E34-G34-H34-I34-J34-K34-L34-M34) -> 0 | O34: 45899
A35: 31 | B35: 122 | C35: =IF(ISERROR(VLOOKUP(B35,CLIENTES!A:B,2,0)),"",VLOOKUP(B35,CLIENTES!A:B,2,0)) -> Yeni Peña | D35: AL HARAMAIN AMBER OUD GOLD UNISEX 2.0 OZ EDP SP | E35: =IF(ISERROR(VLOOKUP(D35,'Lista de Precio '!A:C,3,0)),"",VLOOKUP(D35,'Lista de Precio '!A:C,3,0)) -> 73 | F35: 45838 | G35: 25 | H35: 20 | I35: 28 | N35: =IF(D35="","",E35-G35-H35-I35-J35-K35-L35-M35) -> 0 | O35: 45899
A36: 32 | B36: 123 | C36: =IF(ISERROR(VLOOKUP(B36,CLIENTES!A:B,2,0)),"",VLOOKUP(B36,CLIENTES!A:B,2,0)) -> Kristel Kowaski | D36: DIESEL PLUS PLUS WOMAN 2.5 OZ. EDT | E36: =IF(ISERROR(VLOOKUP(D36,'Lista de Precio '!A:C,3,0)),"",VLOOKUP(D36,'Lista de Precio '!A:C,3,0)) -> 40 | F36: 45839 | G36: 15 | H36: 10 | I36: 10 | J36: 5 | N36: =IF(D36="","",E36-G36-H36-I36-J36-K36-L36-M36) -> 0 | O36: 45901
A37: 33 | B37: 124 | C37: =IF(ISERROR(VLOOKUP(B37,CLIENTES!A:B,2,0)),"",VLOOKUP(B37,CLIENTES!A:B,2,0)) -> Edgar Oati | D37: ΑΝΤΟΝΙΟO BANDERAS BLUE SEDUCTION MEN 3.4 OZ EDT SP-NEW UPC | E37: =IF(ISERROR(VLOOKUP(D37,'Lista de Precio '!A:C,3,0)),"",VLOOKUP(D37,'Lista de Precio '!A:C,3,0)) -> 40 | F37: 45839 | G37: 20 | H37: 20 | N37: =IF(D37="","",E37-G37-H37-I37-J37-K37-L37-M37) -> 0 | O37: 45901
A38: 34 | B38: 125 | C38: =IF(ISERROR(VLOOKUP(B38,CLIENTES!A:B,2,0)),"",VLOOKUP(B38,CLIENTES!A:B,2,0)) -> Yerika Angulo | D38: PERRY ELLIS 360 CORAL WOMEN 3.4 OZ. EDP SP | E38: =IF(ISERROR(VLOOKUP(D38,'Lista de Precio '!A:C,3,0)),"",VLOOKUP(D38,'Lista de Precio '!A:C,3,0)) -> 45 | F38: 45839 | G38: 10 | H38: 10 | I38: 10 | J38: 10 | N38: =IF(D38="","",E38-G38-H38-I38-J38-K38-L38-M38) -> 5 | O38: 45839
A39: 35 | B39: 126 | C39: =IF(ISERROR(VLOOKUP(B39,CLIENTES!A:B,2,0)),"",VLOOKUP(B39,CLIENTES!A:B,2,0)) -> Paola Gomez | D39: BRITNEY SPEARS FANTASY HIDDEN WOMAN 3.3 OZ. EDP SP | E39: =IF(ISERROR(VLOOKUP(D39,'Lista de Precio '!A:C,3,0)),"",VLOOKUP(D39,'Lista de Precio '!A:C,3,0)) -> 45 | F39: 45839 | G39: 10 | H39: 20 | I39: 15 | N39: =IF(D39="","",E39-G39-H39-I39-J39-K39-L39-M39) -> 0 | O39: 45839
A40: 36 | B40: 127 | C40: =IF(ISERROR(VLOOKUP(B40,CLIENTES!A:B,2,0)),"",VLOOKUP(B40,CLIENTES!A:B,2,0)) -> Arma Neliz | D40: BRITNEY SPEARS FANTASY HIDDEN WOMAN 3.3 OZ. EDP SP | E40: =IF(ISERROR(VLOOKUP(D40,'Lista de Precio '!A:C,3,0)),"",VLOOKUP(D40,'Lista de Precio '!A:C,3,0)) -> 45 | F40: 45839 | N40: =IF(D40="","",E40-G40-H40-I40-J40-K40-L40-M40) -> 45 | O40: 45901
A41: 37 | B41: 128 | C41: =IF(ISERROR(VLOOKUP(B41,CLIENTES!A:B,2,0)),"",VLOOKUP(B41,CLIENTES!A:B,2,0)) -> Ciribeth Guerrero | D41: LATTAFA YARA MOI WOMEN 3.4 OZ EDP SP | E41: =IF(ISERROR(VLOOKUP(D41,'Lista de Precio '!A:C,3,0)),"",VLOOKUP(D41,'Lista de Precio '!A:C,3,0)) -> 55 | F41: 45839 | N41: =IF(D41="","",E41-G41-H41-I41-J41-K41-L41-M41) -> 55 | O41: 45901
A42: 38 | B42: 128 | C42: =IF(ISERROR(VLOOKUP(B42,CLIENTES!A:B,2,0)),"",VLOOKUP(B42,CLIENTES!A:B,2,0)) -> Ciribeth Guerrero | D42: Afnan Violet Bouquet woman (LUIS) | E42: =IF(ISERROR(VLOOKUP(D42,'Lista de Precio '!A:C,3,0)),"",VLOOKUP(D42,'Lista de Precio '!A:C,3,0)) -> 55 | F42: 45839 | G42: 20 | H42: 20 | N42: =IF(D42="","",E42-G42-H42-I42-J42-K42-L42-M42) -> 15 | O42: 45901 | P42: 55$ Luis
A43: 39 | B43: 102 | C43: =IF(ISERROR(VLOOKUP(B43,CLIENTES!A:B,2,0)),"",VLOOKUP(B43,CLIENTES!A:B,2,0)) -> Genesis Torres | D43: DIESEL PLUS PLUS WOMAN 2.5 OZ. EDT | E43: =IF(ISERROR(VLOOKUP(D43,'Lista de Precio '!A:C,3,0)),"",VLOOKUP(D43,'Lista de Precio '!A:C,3,0)) -> 40 | F43: 45839 | G43: 20 | H43: 20 | N43: =IF(D43="","",E43-G43-H43-I43-J43-K43-L43-M43) -> 0 | O43: 45901
A44: 40 | B44: 129 | C44: =IF(ISERROR(VLOOKUP(B44,CLIENTES!A:B,2,0)),"",VLOOKUP(B44,CLIENTES!A:B,2,0)) -> Reinaldo Davila | D44: AFNAN 9PM REBEL (RED) UNISEX 3.4 OZ EDP SP | E44: =IF(ISERROR(VLOOKUP(D44,'Lista de Precio '!A:C,3,0)),"",VLOOKUP(D44,'Lista de Precio '!A:C,3,0)) -> 65 | F44: 45839 | G44: 10 | H44: 15 | I44: 10 | J44: 20 | K44: 10 | N44: =IF(D44="","",E44-G44-H44-I44-J44-K44-L44-M44) -> 0 | O44: 45901
...

Sheet CLIENTES
A3: Codigo | B3: Cliente | C3: Numero | D3: referencia
A4: 101 | B4: Gabriela Maykel | C4: +58 426-6814186
A5: 102 | B5: Genesis Torres | C5: +58 424-7352963
A6: 103 | B6: Wenrit Corro
A7: 104 | B7: Maria Quintana
A8: 105 | B8: Yonathan Gamez
A9: 106 | B9: Nani | D9: Yelismar
A10: 107 | B10: Yusneidy Alarcon | D10: Yelismar
A11: 108 | B11: Yajaira | D11: Yelismar
A12: 109 | B12: Maria Mercedez
A13: 110 | B13: Milana Medina
A14: 111 | B14: Gregorio Salcedo
A15: 112 | B15: Anyi Castillo
A16: 113 | B16: Maricela Balza
A17: 114 | B17: Rosangela Medina
A18: 115 | B18: Yuli R
A19: 116 | B19: Neuris
A20: 117 | B20: Yelismar Solano
A21: 118 | B21: Wilson Gonzales
A22: 119 | B22: Hector Hidromaticos
A23: 120 | B23: Junior Hidromaticos
... A88: 185 | B88: Alvaro Dugarte

Sheet Hoja1
A4: N° | B4: Codigo | C4: Cliente | D4: Producto | E4: Precio | F4: Fecha | G4: Pago 1 | H4: Pago 2 | I4: Pago 3 | J4: Pago 4 | K4: Pago 5 | L4: Pago 6 | M4: Pago 7 | N4: Por pagar | O4: Fin Credito | P4: NOTA | S4: MENSAJE DE COBROO
A5: 1 | B5: 103 | C5: =IF(ISERROR(VLOOKUP(B5,CLIENTES!A:B,2,0)),"",VLOOKUP(B5,CLIENTES!A:B,2,0)) -> Wenrit Corro | D5: BRITNEY SPEARS FANTASY HIDDEN WOMAN 3.3 OZ. EDP SP | E5: =IF(ISERROR(VLOOKUP(D5,'Lista de Precio '!A:C,3,0)),"",VLOOKUP(D5,'Lista de Precio '!A:C,3,0)) -> 45 | F5: 45837 | G5: 10 | H5: 10 | I5: 5 | J5: 10 | K5: 5 | L5: 5 | N5: =IF(D5="","",E5-G5-H5-I5-J5-K5-L5-M5) -> 0 | O5: 45898
A6: 2
A7: 3
A8: 4
A9: 5

Sheet IMPRIMIR PRECIOS
A1: PRODUCTO | B1: DIVISAS | C1: TASA EURO | D1: BCV EURO
A2: AFNAN 9AM DIVE UNISEX 5.0 OZ EDP SP | B2: 70 | C2: =(B2*32.35/100)+B2 -> 92.645 | D2: =(B2*13.31/100)+B2 -> 79.317
A3: AFNAN 9AM WOMEN 3.4 OZ. EDP SP | B3: 60 | C3: =(B3*32.35/100)+B3 -> 79.41 | D3: =(B3*13.31/100)+B3 -> 67.986
A4: AFNAN 9PM ELIXIR UNISEX 3.4 OZ PARFUM INTENSE | B4: 65 | C4: =(B4*32.35/100)+B4 -> 86.0275 | D4: =(B4*13.31/100)+B4 -> 73.6515
A5: AFNAN 9PM MEN 3.4 OZ. EDP SP | B5: 60 | C5: =(B5*32.35/100)+B5 -> 79.41 | D5: =(B5*13.31/100)+B5 -> 67.986
A6: AFNAN 9PM WOMEN 3.4 OZ.EDP SP | B6: 60 | C6: =(B6*32.35/100)+B6 -> 79.41 | D6: =(B6*13.31/100)+B6 -> 67.986
A7: ARIANA GRANDE CLOUD PINK WOMEN 3.4 OZ EDP SP | B7: 90 | C7: =(B7*32.35/100)+B7 -> 119.115 | D7: =(B7*13.31/100)+B7 -> 101.979
A8: ARIANA GRANDE CLOUD WOMEN 3.4 OZ. EDP SP | B8: 90 | C8: =(B8*32.35/100)+B8 -> 119.115 | D8: =(B8*13.31/100)+B8 -> 101.979
A9: ARIANA GRANDE SWEET LIKE CANDY WOMEN 3.4 OZ. EDP SP | B9: 80 | C9: =(B9*32.35/100)+B9 -> 105.88 | D9: =(B9*13.31/100)+B9 -> 90.648
A10: ARMAF CLUB DE NUIT WOMEN 2.37 OZ EXTRAIT DE PARFUM SP | B10: 60 | C10: =(B10*32.35/100)+B10 -> 79.41 | D10: =(B10*13.31/100)+B10 -> 67.986
A11: ARMAF CHECKMATE QUEEN WOMEN 3.4 OZ EDP SP | B11: 60 | C11: =(B11*32.35/100)+B11 -> 79.41 | D11: =(B11*13.31/100)+B11 -> 67.986
A12: ARMAF ODYSSEY BLACK MEN 3.4 OZ. EDP SP | B12: 60 | C12: =(B12*32.35/100)+B12 -> 79.41 | D12: =(B12*13.31/100)+B12 -> 67.986
A13: ARMAF ODYSSEY CANDEE WOMEN 3.4 OZ EDP SP | B13: 60 | C13: =(B13*32.35/100)+B13 -> 79.41 | D13: =(B13*13.31/100)+B13 -> 67.986
... A44: PARIS HILTON WOMEN 3.4 OZ. EDP SP | B44: 50 | C44: =(B44*32.35/100)+B44 -> 66.175 | D44: =(B44*13.31/100)+B44 -> 56.655

Sheet Hoja2
A1: PEDIDO 12/2025 | B1: INV
A2: ADIDAS DYNAMIC PULSE MEN 3.4 OZ. SP (NEW UPC) | B2: 1
A3: ADIDAS ICE DIVE MEN 3.4 OZ. EDT | B3: 2
A4: ADIDAS VICTORY LEAGUE MEN 3.4 OZ. EDT SP -NEW UPC | B4: 2
A5: AFNAN 9AM DIVE UNISEX 5.0 OZ EDP SP | B5: 1
A6: AFNAN 9PM ELIXIR UNISEX 3.4 OZ PARFUM INTENSE | B6: 1
A7: AFNAN 9PM MEN 3.4 OZ. EDP SP | B7: 3
A8: AFNAN 9PM REBEL (RED) UNISEX 3.4 OZ EDP SP | B8: 1
A9: AL HARAMAIN AMBER OUD AQUA DUBAI UNISEX 3.4 OZ EXTRAIT DE PARFUM | B9: 1
A10: ANTONIO BANDERAS BLACK SEDUCTION MEN 3.4 OZ. EDT SP-NEW UPC | B10: 3
A11: ARMAF CLUB DE NUIT INTENSE MEN 3.6 OZ. EDT SP | B11: 2
A12: ARMAF CLUB DE NUIT MILESTONE MEN 3.6 OZ. EDP | B12: 1
A13: ARMAF CLUB DE NUIT PRECIEUX 1 EXTRAIT DE PARFUM FOR MEN 1.85 OZ | B13: 1
... A62: SWISS ARMY ALTITUDE MEN 3.4 OZ. EDT SPRAY | B62: 4
A63: TOTALES | B63: =SUM(B2:B62) -> 111
