Workbook

Sheet PRESTAMOS
A1: REGISTRO DE PRESTAMOS 2024
A3: DATOS PRESTAMO | K3: ACTUALIZACION | L3: 23/3/2024 9:27AM | N3: MESES
A4: CODIGO | B4: FECHA DE PRESTAMO | C4: NOMBRE DE CLIENTE | D4: CAPITAL PRESTADO | E4: CAPITAL POR PAGAR | F4: INTERES % | G4: FECHA DE PAGO | H4: GARANTIA | I4: INTERES A PAGAR $ | J4: ABONOS | K4: FECHA ABONO | L4: OBSERVACION | N4: DICIEMBRE | O4: ENERO | P4: FEBRERO | Q4: MARZO | R4: ABRIL | S4: MAYO | T4: JUNIO | U4: JULIO | V4: AGOSTO | W4: SEPTIEMBRE | X4: OCTUBRE | Y4: NOVIEMBRE | Z4: DICIEMBRE | AA4: ENERO | AB4: FEBRERO | AC4: MARZO | AD4: ABRIL | AE4: MAYO
A5: 104 | B5: 45611 | C5: =+VLOOKUP(A5,CLIENTES!$A$4:$B$487,2,FALSE) -> LUIS WENRIT | D5: 210 | E5: =D5-J5 -> 210 | F5: 0.15 | G5: 45611 | H5: SIN GARANTIA | I5: =(E5*F5)/1 -> 31.5 | J5: 0
A6: 111 | B6: 45649 | C6: =+VLOOKUP(A6,CLIENTES!$A$4:$B$487,2,FALSE) -> MIGUEL PEREZ | D6: 100 | E6: =D6-J6 -> 100 | F6: 0.15 | G6: 45649 | H6: SIN GARANTIA | I6: =(E6*F6)/1 -> 15 | J6: 0 | S6: 10 | T6: 15 | U6: 15
A7: 113 | B7: 45288 | C7: =+VLOOKUP(A7,CLIENTES!$A$4:$B$487,2,FALSE) -> REINALDO DAVILA | D7: 55 | E7: =D7-J7 -> 55 | F7: 0.15 | G7: 45319 | H7: SIN GARANTIA | I7: =(E7*F7)/1 -> 8.25 | J7: 0
A8: 122 | B8: 45377 | C8: =+VLOOKUP(A8,CLIENTES!$A$4:$B$487,2,FALSE) -> ANABERLY RONDON | D8: 1400 | E8: 0 | F8: 0.2 | G8: 45042 | H8: apartamento | I8: =(E8*F8)/1 -> 0 | J8: 14000
A9: 128 | B9: 45458 | C9: =+VLOOKUP(A9,CLIENTES!$A$4:$B$487,2,FALSE) -> DIONY | D9: 150 | E9: =D9-J9 -> 150 | F9: 0.15 | G9: 45480 | H9: SIN GARANTIA | I9: =(E9*F9)/1 -> 22.5 | J9: 0
A10: 130 | B10: 45467 | C10: =+VLOOKUP(A10,CLIENTES!$A$4:$B$487,2,FALSE) -> MILANA MEDINA | D10: 100 | E10: =D10-J10 -> 20 | F10: 0.15 | G10: 45467 | H10: SIN GARANTIA | I10: =(E10*F10)/1 -> 3 | J10: 80 | L10: Hermano
A11: 132 | B11: 45475 | C11: =+VLOOKUP(A11,CLIENTES!$A$4:$B$487,2,FALSE) -> NORBEDY ROJAS | D11: 350 | E11: =D11-J11 -> 100 | F11: 0.1 | G11: 45506 | H11: SIN GARANTIA | I11: =(E11*F11)/1 -> 10 | J11: 250 | L11: se agrego 150 6/1/2025 Diana | N11: 45597
A12: 135 | B12: 45485 | C12: =+VLOOKUP(A12,CLIENTES!$A$4:$B$487,2,FALSE) -> JACKSON JAIMES | D12: 150 | E12: 150 | F12: 0.2 | G12: 45516 | H12: SIN GARANTIA | I12: =(E12*F12)/1 -> 30 | J12: 0
A13: 142 | B13: 45517 | C13: =+VLOOKUP(A13,CLIENTES!$A$4:$B$487,2,FALSE) -> LISBETH MORALES | D13: 500 | E13: =D13-J13 -> 400 | F13: 0.15 | G13: 45517 | H13: SIN GARANTIA | I13: =(E13*F13)/1 -> 60 | J13: 100 | T13: 25 | U13: 25 | V13: pago 90 | W13: pago 60 | X13: 90 | Y13: 60
A14: 107 | B14: 45548 | C14: =+VLOOKUP(A14,CLIENTES!$A$4:$B$487,2,FALSE) -> MAYKEL DAVILA | D14: 200 | E14: =D14-J14 -> 200 | F14: 0.2 | G14: 45548 | H14: SIN GARANTIA | I14: =(E14*F14)/1 -> 40 | J14: 0 | L14: Danco
A15: 147 | B15: 45582 | C15: =+VLOOKUP(A15,CLIENTES!$A$4:$B$487,2,FALSE) -> RICARDO | D15: 50 | E15: =D15-J15 -> 18 | F15: 0.15 | G15: 45582 | H15: SIN GARANTIA | I15: =(E15*F15)/1 -> 2.7 | J15: 32
A16: 104 | B16: 45675 | C16: =+VLOOKUP(A16,CLIENTES!$A$4:$B$487,2,FALSE) -> LUIS WENRIT | D16: 260 | E16: =D16-J16 -> 0 | F16: 0.15 | G16: 45675 | I16: =(E16*F16)/1 -> 0 | J16: 260 | L16: Capital Luis + 60 cesar | N16: N/A | O16: N/A
A17: 154 | B17: 45672 | C17: =+VLOOKUP(A17,CLIENTES!$A$4:$B$487,2,FALSE) -> WENRTIR CORRO | D17: 350 | E17: =D17-J17 -> 0 | F17: 0.1 | G17: 45672 | I17: =(E17*F17)/1 -> 0 | J17: 350 | N17: N/A | O17: N/A
A18: 105 | B18: 45703 | C18: =+VLOOKUP(A18,CLIENTES!$A$4:$B$487,2,FALSE) -> EDUARDO JUEZ | D18: 300 | E18: =D18-J18 -> 300 | F18: 0.15 | G18: 45724 | I18: =(E18*F18)/1 -> 45 | J18: 0 | N18: N/A | O18: N/A | P18: N/A | Z18: 45
A19: 105 | B19: 30/2/2025 | C19: =+VLOOKUP(A19,CLIENTES!$A$4:$B$487,2,FALSE) -> EDUARDO JUEZ | D19: 350 | E19: =D19-J19 -> 350 | F19: 0.15 | G19: 45713 | I19: =(E19*F19)/1 -> 52.5 | J19: 0 | N19: N/A | O19: N/A | P19: N/A | Z19: 5
A20: 104 | B20: 45752 | C20: =+VLOOKUP(A20,CLIENTES!$A$4:$B$487,2,FALSE) -> LUIS WENRIT | D20: 220 | E20: =D20-J20 -> 220 | F20: 0.15 | G20: 5/42025 | H20: Reloj | I20: =(E20*F20)/1 -> 33 | J20: 0 | L20: Jeny | N20: N/A | O20: N/A | P20: N/A | Q20: N/A | R20: N/A
A21: 131 | B21: 45764 | C21: =+VLOOKUP(A21,CLIENTES!$A$4:$B$487,2,FALSE) -> VICTOR DELGADO | D21: 90 | E21: 90 | F21: 0.2 | G21: 45764 | I21: =(E21*F21)/1 -> 18 | J21: 0 | L21: 50 y se agregan 40 que pidio | N21: N/A | O21: N/A | P21: N/A | Q21: N/A | R21: N/A
A22: 104 | B22: 45777 | C22: =+VLOOKUP(A22,CLIENTES!$A$4:$B$487,2,FALSE) -> LUIS WENRIT | D22: 500 | E22: =D22-J22 -> 200 | F22: 0.1 | G22: 45768 | I22: =(E22*F22)/1 -> 20 | J22: 300 | N22: N/A | O22: N/A | P22: N/A | Q22: N/A | R22: N/A
A23: 104 | B23: 45772 | C23: =+VLOOKUP(A23,CLIENTES!$A$4:$B$487,2,FALSE) -> LUIS WENRIT | D23: 100 | E23: =D23-J23 -> 50 | F23: 0.15 | G23: 45/5/2025 | I23: =(E23*F23)/1 -> 7.5 | J23: 50 | L23: MISE | N23: N/A | O23: N/A | P23: N/A | Q23: N/A | R23: N/A
A24: 131 | B24: 45773 | C24: =+VLOOKUP(A24,CLIENTES!$A$4:$B$487,2,FALSE) -> VICTOR DELGADO | D24: 80 | E24: =D24-J24 -> 80 | F24: 0.2 | G24: 45773 | I24: =(E24*F24)/1 -> 16 | J24: 0 | N24: N/A | O24: N/A | P24: N/A | Q24: N/A | R24: N/A | S24: N/A | W24: debe 6$
A25: 139 | B25: 45774 | C25: =+VLOOKUP(A25,CLIENTES!$A$4:$B$487,2,FALSE) -> CESAR RUIZ | D25: 100 | E25: =D25-J25 -> 100 | F25: 0.15 | G25: 45774 | I25: =(E25*F25)/1 -> 15 | J25: 0 | N25: N/A | O25: N/A | P25: N/A | Q25: N/A | R25: N/A | S25: N/A
A26: 107 | B26: 45782 | C26: =+VLOOKUP(A26,CLIENTES!$A$4:$B$487,2,FALSE) -> MAYKEL DAVILA | D26: 150 | E26: =D26-J26 -> 150 | F26: 0.15 | G26: 45813 | I26: =(E26*F26)/1 -> 22.5 | J26: 0 | L26: Maykel | N26: N/A | O26: N/A | P26: N/A | Q26: N/A | R26: N/A | S26: N/A
A27: 104 | B27: 45792 | C27: =+VLOOKUP(A27,CLIENTES!$A$4:$B$487,2,FALSE) -> LUIS WENRIT | D27: 160 | E27: =D27-J27 -> 160 | F27: 0.15 | G27: 45817 | I27: =(E27*F27)/1 -> 24 | J27: 0 | L27: Carlos Rodriguez | N27: N/A | O27: N/A | P27: N/A | Q27: N/A | R27: N/A | S27: N/A
A28: 104 | B28: 45807 | C28: =+VLOOKUP(A28,CLIENTES!$A$4:$B$487,2,FALSE) -> LUIS WENRIT | D28: 500 | E28: =D28-J28 -> 400 | F28: 0.15 | G28: 45804 | I28: =(E28*F28)/1 -> 60 | J28: 100 | L28: Lisbeth | N28: N/A | O28: N/A | P28: N/A | Q28: N/A | R28: N/A | S28: N/A | X28: 60 | Y28: 60
A29: 168 | B29: 45833 | C29: =+VLOOKUP(A29,CLIENTES!$A$4:$B$487,2,FALSE) -> KAREN VERGARA | D29: 200 | E29: =D29-J29 -> 200 | F29: 0.15 | G29: 45843 | I29: =(E29*F29)/1 -> 30 | J29: 0 | N29: N/A | O29: N/A | P29: N/A | Q29: N/A | R29: N/A | S29: N/A | T29: N/A
A30: 150 | B30: 45809 | C30: =+VLOOKUP(A30,CLIENTES!$A$4:$B$487,2,FALSE) -> MARIA QUINTANA GUAYABA | D30: 100 | E30: =D30-J30 -> 26 | F30: 0.1 | G30: 45809 | I30: =(E30*F30)/1 -> 2.6 | J30: 74 | N30: N/A | O30: N/A | P30: N/A | Q30: N/A | R30: N/A | S30: N/A | T30: N/A
A31: 161 | B31: 45861 | C31: =+VLOOKUP(A31,CLIENTES!$A$4:$B$487,2,FALSE) -> MAYRA DAR | D31: 160 | E31: =D31-J31 -> 160 | F31: 0.15 | G31: 45892 | I31: =(E31*F31)/1 -> 24 | J31: 0 | L31: BCV | N31: N/A | O31: N/A | P31: N/A | Q31: N/A | R31: N/A | S31: N/A | T31: N/A | U31: N/A
A32: 131 | B32: 45878 | C32: =+VLOOKUP(A32,CLIENTES!$A$4:$B$487,2,FALSE) -> VICTOR DELGADO | D32: 75 | E32: =D32-J32 -> 40 | F32: 0.2 | G32: 45939 | I32: =(E32*F32)/1 -> 8 | J32: 35 | L32: Efectivo | N32: N/A | O32: N/A | P32: N/A | Q32: N/A | R32: N/A | S32: N/A | T32: N/A | U32: N/A | V32: N/A
A33: 130 | B33: 45883 | C33: =+VLOOKUP(A33,CLIENTES!$A$4:$B$487,2,FALSE) -> MILANA MEDINA | D33: 120 | E33: =D33-J33 -> 90 | F33: 0.15 | G33: 45914 | I33: =(E33*F33)/1 -> 13.5 | J33: 30 | L33: BCV | N33: N/A | O33: N/A | P33: N/A | Q33: N/A | R33: N/A | S33: N/A | T33: N/A | U33: N/A | V33: N/A
A34: 173 | B34: 45898 | C34: =+VLOOKUP(A34,CLIENTES!$A$4:$B$487,2,FALSE) -> Danco | D34: 500 | E34: =D34-J34 -> 100 | F34: 0.15 | G34: 45929 | I34: =(E34*F34)/1 -> 15 | J34: 400 | L34: EFECTIVO / abono a las semana 200 | N34: N/A | O34: N/A | P34: N/A | Q34: N/A | R34: N/A | S34: N/A | T34: N/A | U34: N/A | V34: N/A | W34: debe 4 | AD34: debe 8
A35: 174 | B35: 45898 | C35: =+VLOOKUP(A35,CLIENTES!$A$4:$B$487,2,FALSE) -> Miguel Gonzales | D35: 200 | E35: =D35-J35 -> 34 | F35: 0.15 | G35: 45929 | I35: =(E35*F35)/1 -> 5.1 | J35: 166 | L35: EFECTIVO/Luis | N35: N/A | O35: N/A | P35: N/A | Q35: N/A | R35: N/A | S35: N/A | T35: N/A | U35: N/A | V35: N/A | W35: 20 | X35: 20 | Y35: 40 | Z35: 20
A36: 104 | B36: 45901 | C36: =+VLOOKUP(A36,CLIENTES!$A$4:$B$487,2,FALSE) -> LUIS WENRIT | D36: 50 | E36: =D36-J36 -> 50 | F36: 0.15 | G36: 45931 | I36: =(E36*F36)/1 -> 7.5 | J36: 0 | L36: Leidy | N36: N/A | O36: N/A | P36: N/A | Q36: N/A | R36: N/A | S36: N/A | T36: N/A | U36: N/A | V36: N/A | W36: N/A
A37: 104 | B37: 45915 | C37: =+VLOOKUP(A37,CLIENTES!$A$4:$B$487,2,FALSE) -> LUIS WENRIT | D37: 170 | E37: =D37-J37 -> 25.65 | F37: 0.15 | G37: 45931 | I37: =(E37*F37)/1 -> 3.8475 | J37: 144.35 | L37: BRAYAN | N37: N/A | O37: N/A | P37: N/A | Q37: N/A | R37: N/A | S37: N/A | T37: N/A | U37: N/A | V37: N/A | W37: N/A
A38: 143 | B38: 45903 | C38: =+VLOOKUP(A38,CLIENTES!$A$4:$B$487,2,FALSE) -> ABG. JOSE GREGORIO | D38: 100 | E38: =D38-J38 -> 100 | F38: 0.15 | G38: 45933 | I38: =(E38*F38)/1 -> 15 | J38: 0 | L38: BCV | N38: N/A | O38: N/A | P38: N/A | Q38: N/A | R38: N/A | S38: N/A | T38: N/A | U38: N/A | V38: N/A | W38: N/A
A39: 114 | B39: 45928 | C39: =+VLOOKUP(A39,CLIENTES!$A$4:$B$487,2,FALSE) -> ALBER UZCATEGUI | D39: 1200 | E39: =D39-J39 -> 840 | F39: 0.1 | G39: 45958 | I39: =(E39*F39)/1 -> 84 | J39: 360 | N39: N/A | O39: N/A | P39: N/A | Q39: N/A | R39: N/A | S39: N/A | T39: N/A | U39: N/A | V39: N/A | W39: N/A
A40: 131 | B40: 45934 | C40: =+VLOOKUP(A40,CLIENTES!$A$4:$B$487,2,FALSE) -> VICTOR DELGADO | D40: 60 | E40: =D40-J40 -> 60 | F40: 0.2 | G40: 45965 | I40: =(E40*F40)/1 -> 12 | J40: 0 | L40: EURO | N40: N/A | O40: N/A | P40: N/A | Q40: N/A | R40: N/A | S40: N/A | T40: N/A | U40: N/A | V40: N/A | W40: N/A | X40: N/A
A41: 131 | B41: 45946 | C41: =+VLOOKUP(A41,CLIENTES!$A$4:$B$487,2,FALSE) -> VICTOR DELGADO | D41: 25 | E41: =D41-J41 -> 25 | F41: 0.2 | I41: =(E41*F41)/1 -> 5 | J41: 0 | L41: EURO | N41: N/A | O41: N/A | P41: N/A | Q41: N/A | R41: N/A | S41: N/A | T41: N/A | U41: N/A | V41: N/A | W41: N/A | X41: N/A
...

Sheet CLIENTES
A1: BASE DE DATOS CLIENTE
A3: CODIGO | B3: NOMBRE DEL CLIENTE | C3: CEDULA | D3: TELEFONO | E3: CORREO | F3: DIREECION | G3: REFERENCIA
A4: 101 | B4: DANI FERNANADEZ | D4: 4120747332 | F4: DAR MERIDA | G4: CSAR
A5: 102 | B5: YAJAIRA YELISMAR | D5: 4262121346 | F5: ALFREDO LARA | G5: YELISMAR
A6: 103 | B6: CARLOS ALBARRAN | D6: 4147077056 | F6: EL PARAISO LOS CUROS | G6: CSAR
A7: 104 | B7: LUIS WENRIT | D7: 4149743408 | F7: EJIDO | G7: WENRIT
A8: 105 | B8: EDUARDO JUEZ | D8: 4247401646 | F8: CJP MERIDA | G8: WENDY LOBELI
A9: 106 | B9: DIANA ARDILA | D9: 4147455545 | F9: DAR MERIDA | G9: CSAR
A10: 107 | B10: MAYKEL DAVILA | D10: 4147237571 | F10: PADRE DUQUE 267 | G10: CSAR
A11: 108 | B11: GORDO MANUEL | D11: 4145310101 | F11: ASOPRIETO | G11: CSAR
A12: 109 | B12: MARIA GONZALES | C12: 19048430 | D12: 4261780802 | F12: ASOPRIETO | G12: MANUEL
A13: 110 | B13: FERNANDO ABARRAN | D13: 4247644073 | F13: LOS CUROS PARAISO | G13: CSAR
A14: 111 | B14: MIGUEL PEREZ | D14: 4247612703 | F14: LA MILAGROSA | G14: CSAR
A15: 112 | B15: JHOSWAL SALINAS | C15: 26749824 | D15: 4162797147 | F15: LOS CUROS PARAISO | G15: PUCHINI
A16: 113 | B16: REINALDO DAVILA | D16: 4127985171 | F16: PADRE DUQUE 267 | G16: CSAR
A17: 114 | B17: ALBER UZCATEGUI | D17: 4147352473 | F17: PADRE DUQUE 265 | G17: CSAR
A18: 115 | B18: LILIANA DURAN | D18: 4149380034 | F18: DAR MERIDA | G18: CSAR
A19: 116 | B19: PUCHINI | D19: 4120788399 | F19: LOS CUROS | G19: CSAR
A20: 117 | B20: JENIFFER YELISMAR | D20: 4264468622 | F20: EL PALMO | G20: YELISMAR
A21: 118 | B21: YULIMAR PEÑA | D21: 4120780922 | F21: CENTENARIO | G21: CESAR
A22: 119 | B22: RAFAEL MOLINA | D22: 4247439757 | F22: OATI | G22: CESAR
A23: 120 | B23: JONATAN OSORIO | D23: 4247738514 | F23: EJIDO CAYE AYACUCHO | G23: LUIS
A24: 121 | B24: VALENTINA ALBERT | D24: 4247557595 | F24: BOTICARIO | G24: ALBERT UZCATEGUI
A25: 122 | B25: ANABERLY RONDON | C25: 17523212 | D25: 4168767228 | F25: EJIDO | G25: ALBERT UZCATEGUI
A26: 123 | B26: JOSE GREGORIO KOLORES | D26: 4126461289 | F26: KOLORES | G26: YELISMAR
A27: 124 | B27: CLIENTE NANITO | F27: ANDINITO | G27: NANO
A28: 125 | B28: LINDA ALBERT | D28: 4127238782 | F28: BOTICARIO | G28: ALBER UZCATEGUI
A29: 126 | B29: ALBARO DUGARTE | D29: 5674756237 | F29: LOS CUROS - CHILE | G29: CESAR CHOURIO
A30: 127 | B30: POLLA | F30: EJIDO SANMIGUE | G30: ALBER UZCATEGUI
A31: 128 | B31: DIONY | D31: 4247327103 | F31: TRUBUNAL EDF HERMES | G31: CESAR CHOURIO
A32: 129 | B32: YOSBER | D32: 4121361910 | F32: EJIDO | G32: CESAR CHOURIO
A33: 130 | B33: MILANA MEDINA | D33: 4166427065 | F33: DAR MERIDA | G33: CESAR CHOURIO
A34: 131 | B34: VICTOR DELGADO | D34: 4247070114 | F34: PUENTE LA PEDREGOSA | G34: VALENTINA ALBERT
A35: 132 | B35: NORBEDY ROJAS | F35: CJP MERIDA | G35: CESAR CHOURIO
A36: 133 | B36: MARIELBA PUCHINI | F36: LOS CUROS | G36: PUCHINI
A37: 134 | B37: MARIA MERCEDEZ | D37: 4247284861 | F37: DAR MERIDA | G37: CESAR
A38: 135 | B38: JACKSON JAIMES | D38: +58 414-7088044 | F38: DAR MERIDA | G38: CESAR
A39: 136 | B39: JONY LACRUZ | F39: LOS CUROS | G39: CESAR
A40: 137 | B40: IVAN RODRIGUEZ | F40: DAR MERIDA | G40: CESAR
A41: 138 | B41: MAHINET UZCATEGUI | F41: KOLORES MERIDA | G41: CESAR
...

Sheet MANEJO CAPITALES Y EFECTIVO
B3: EFECTIVO
B4: DENOMINACION | C4: 100 | D4: 50 | E4: 20 | F4: 10 | G4: 5
B5: CANTIDAD | C5: 10 | D5: 1 | E5: 20 | F5: 11 | G5: 7
B6: TOTAL | C6: =C5*C4 -> 1000 | D6: =D5*D4 -> 50 | E6: =E5*E4 -> 400 | F6: =F5*F4 -> 110 | G6: =G5*G4 -> 35 | H6: =SUM(C6:G6) -> 1595
B7: CAPITAL EN CAJA
B9: BANCAMIGA | C9: 0 | D9: EFECTIVO | E9: 0
B11: CAPTAL ANTONY | C11: 2890 | E11: Prestados | F11: 1800
B12: Disponible | C12: =C11-F11 -> 1090
B15: CONTEJO DE CAJA
B16: EFECTIVO
B17: DENOMINACION | C17: 0 | D17: 0 | E17: 0 | F17: 0 | G17: 0
B18: CANTIDAD | C18: 16 | D18: 0 | E18: 2 | F18: 0 | G18: 0
B19: TOTAL | C19: =C18*C17 -> 0 | D19: =D18*D17 -> 0 | E19: =E18*E17 -> 0 | F19: =F18*F17 -> 0 | G19: =G18*G17 -> 0
B20: CAPITAL EN CAJA | C20: =C19+D19+E19+F19+G19 -> 0
B22: efectivo por cobrar | C22: 355
B23: intereses vencidos
B24: Binance | C24: 260
B25: biget | C25: 60
B26: bibit | C26: 0
B29: Total Disponoble | C29: =C7+C22+C24+C25+C26 -> 675 | F29: 4

Sheet Hoja1
